Workbook

Sheet Planilha1
B3: Média Gols (xG)
A4: Time 1 (Casa) | B4: =C18*C20*C23 -> 0.91391466 | N4: CASA | U4: MERCADO (1, X e 2)
A5: Time 2 (Fora) | B5: =C19*C21*C22 -> 0.39072356 | N5: 0 | O5: 1 | P5: 2 | Q5: 3 | R5: 4 | S5: 5 | U5: CASA (1) | V5: =SUM(O6,P6,P7,Q6,Q7,Q8,R6,R7,R8,R9,S6,S7,S8,S9,S10) -> 0.46987808 | X5: MERCADO DE GOLS | AB5: MERCADO AMBOS (BTTS)
L6: FORA | M6: 0 | N6: =E8*E9 -> 0.27127066 | O6: =F8*$E$9 -> 0.24791823 | P6: =G8*$E$9 -> 0.11328805 | Q6: =H8*$E$9 -> 0.034511871 | R6: =I8*$E$9 -> 0.0078852261 | S6: =J8*$E$9 -> 0.0014412847 | U6: EMPATE (X) | V6: =SUM(N6,O7,P8,Q9,R10,S11) -> 0.37713658 | X6: ACIMA DE MEIIO (+0,5) | Z6: =SUM(N6:S11)-N6 -> 0.72835358 | AB6: SIM | AC6: =SUM(O7:S11) -> 0.19362943
E7: 0 | F7: 1 | G7: 2 | H7: 3 | I7: 4 | J7: 5 | M7: 1 | N7: =$E$8*F9 -> 0.10599184 | O7: =F8*F9 -> 0.096867494 | P7: =G8*$F$9 -> 0.044264311 | Q7: =H8*$F$9 -> 0.013484601 | R7: =I8*$F$9 -> 0.0030809436 | S7: =J8*$F$9 -> 0.00056314391 | U7: FORA (2) | V7: =SUM(N7,N8,N9,N10,N11,O8,O9,O10,O11,P9,P10,P11,Q10,Q11,R11) -> 0.15260958 | X7: ACIMA UM E MEIO (+1,5) | Z7: =SUM(O7,O8,O9,O10,O11,N8,N9,N10,N11,P6,P7,P8,P9,P10,P11,Q6,Q7,Q8,Q9,Q10,Q11,R6,R7,R8,R9,R10,R11,S6,S7,S8,S9,S10,S11) -> 0.37444351 | AB7: NÃO | AC7: =1-AC6 -> 0.80637057
D8: Casa (1) | E8: =(EXP(-$B$4)*($B$4^E7))/FACT(E7) -> 0.40095156 | F8: =(EXP(-$B$4)*($B$4^F7))/FACT(F7) -> 0.36643551 | G8: =(EXP(-$B$4)*($B$4^G7))/FACT(G7) -> 0.16744539 | H8: =(EXP(-$B$4)*($B$4^H7))/FACT(H7) -> 0.051010266 | I8: =(EXP(-$B$4)*($B$4^I7))/FACT(I7) -> 0.011654757 | J8: =(EXP(-$B$4)*($B$4^J7))/FACT(J7) -> 0.0021302907 | M8: 2 | N8: =$E$8*G9 -> 0.020706754 | O8: =G9*F8 -> 0.018924206 | P8: =G8*G9 -> 0.0086475547 | Q8: =H8*$G$9 -> 0.0026343757 | R8: =I8*$G$9 -> 0.00060189863 | S8: =J8*$G$9 -> 0.0001100168 | X8: ACIMA DOIS E MEIO (+2,5) | Z8: =SUM(N9,N10,N11,O8,O9,O10,O11,P7,P8,P9,P10,P11,Q6,Q7,Q8,Q9,Q10,Q11,R6,R7,R8,R9,R10,R11,S6,S7,S8,S9,S10,S11) -> 0.14358121
D9: Fora (2) | E9: =(EXP(-$B$5)*($B$5^E7))/FACT(E7) -> 0.67656716 | F9: =(EXP(-$B$5)*($B$5^F7))/FACT(F7) -> 0.26435073 | G9: =(EXP(-$B$5)*($B$5^G7))/FACT(G7) -> 0.051644029 | H9: =(EXP(-$B$5)*($B$5^H7))/FACT(H7) -> 0.0067261797 | I9: =(EXP(-$B$5)*($B$5^I7))/FACT(I7) -> 0.00065701922 | J9: =(EXP(-$B$5)*($B$5^J7))/FACT(J7) -> 5.1342578e-05 | M9: 3 | N9: =$E$8*H9 -> 0.0026968722 | O9: =H9*F8 -> 0.0024647111 | P9: =H9*G8 -> 0.0011262678 | Q9: =H8*H9 -> 0.00034310421 | R9: =I8*$H$9 -> 7.8391992e-05 | S9: =J8*$H$9 -> 1.4328718e-05 | X9: ABAIXO DOIS E MEIO (-2,5) | Z9: =SUM(P6,O6,N6,N7,N8,O7) -> 0.85604303
M10: 4 | N10: =E8*I9 -> 0.00026343288 | O10: =I9*F8 -> 0.00024075517 | P10: =I9*G8 -> 0.00011001484 | Q10: =I9*H8 -> 3.3514725e-05 | R10: =I8*I9 -> 7.6573996e-06 | S10: =J8*$I$9 -> 1.3996419e-06 | X10: ABAIXO TRÊS E MEIO (-3,5) | Z10: =SUM(N6,O6,P6,P7,O7,N7,N8,O8) -> 0.91923154
M11: 5 | N11: =E8*J9 -> 2.0585887e-05 | O11: =J9*F8 -> 1.8813744e-05 | P11: =J9*G8 -> 8.597078e-06 | Q11: =J9*H8 -> 2.6189985e-06 | R11: =J9*I8 -> 5.9838529e-07 | S11: =J8*J9 -> 1.0937462e-07 | U11: MERCADO DUPLA CHANCE
U12: CASA OU EMPATE (1X) | V12: =V5+V6 -> 0.84701465
U13: EMPATE OU FORA (X2) | V13: =V6+V7 -> 0.52974616
U14: CASA OU FORA (1_2) | V14: =V5+V7 -> 0.62248766
A15: Média de gols mandantes | C15: 1.63 | Q15: DISTÂNCIA DE FINETTI [0,2]
A16: Média de gols visitante | C16: 1.31 | Q16: CASA | S16: =(V5-1)^2+(V6-0)^2+(V7-0)^2 -> 0.44655094
A17: Fator mando de Campo Geral | C17: =LN(C15/C16) -> 0.21855288 | Q17: EMPATE | S17: =(V5-0)^2+(V6-1)^2+(V6-0)^2 -> 0.75097625
A18: Fator Mandante (home factor) | C18: =SQRT(1+C17)*SQRT(1+C17) -> 1.2185529 | Q18: FORA | S18: =(V5-0)^2+(V6-0)^2+(V7-1)^2 -> 1.0810879
A19: Fator Visitante (away factor) | C19: =SQRT(1-C17)*SQRT(1-C17) -> 0.78144712
A20: Média de Gols Marcados Time 1 | C20: 1.5 | P20: PARÂMETROS
A21: Média de gols marcados Time 2 | C21: 1 | P21: α | Q21: =0.071/N6 -> 0.26173122 | R21: =V5*Q22 -> 0.68033021 | S21: CASA
A22: Média de gols sofridos Time 1 | C22: 0.5 | P22: β | Q22: =(1-Q21*V6)/(V5+V7) -> 1.4478867 | R22: =Q21*V6 -> 0.098708416 | S22: EMPATE
A23: Média de gols sofridos Time 2 | C23: 0.5 | R23: =V7*Q22 -> 0.22096138 | S23: FORA

Sheet Planilha2
B3: Média Gols (xG)
A4: Time 1 (Casa) | B4: 1.2 | N4: CASA (alpha e beta) | U4: % DOS PALPITES | X4: % DE GOLS
A5: Time 2 (Fora) | B5: 1 | N5: 0 | O5: 1 | P5: 2 | Q5: 3 | R5: 4 | S5: 5 | U5: CASA | V5: =SUM(O6,P6,P7,Q6,Q7,Q8,R6,R7,R8,R9,S6,S7,S8,S9,S10) -> 0.5441553 | X5: AMBOS | Z5: =SUM(O7:S11) -> 0.59306457
D6: 0 | E6: 1 | F6: 2 | G6: 3 | H6: 4 | I6: 5 | L6: FORA (alpha e beta) | M6: 0 | N6: =N17 -> 0.071 | O6: =E7*$D$8*$R$26 -> 0.17906914 | P6: =F7*$D$8*$R$26 -> 0.10744148 | Q6: =G7*$D$8*$R$26 -> 0.042976593 | R6: =H7*$D$8*$R$26 -> 0.012892978 | S6: =I7*$D$8*$R$26 -> 0.0030943147 | U6: EMPATE | V6: =SUM(N6,O7,P8,Q9,R10,S11) -> 0.31151564 | X6: ACIMA DE MEIO | Z6: =SUM(N6:S11)-N6 -> 1.1947074
C7: Casa (_1) | D7: =(EXP(-$B$4)*($B$4^D6))/FACT(D6) -> 0.30119421 | E7: =(EXP(-$B$4)*($B$4^E6))/FACT(E6) -> 0.36143305 | F7: =(EXP(-$B$4)*($B$4^F6))/FACT(F6) -> 0.21685983 | G7: =(EXP(-$B$4)*($B$4^G6))/FACT(G6) -> 0.086743933 | H7: =(EXP(-$B$4)*($B$4^H6))/FACT(H6) -> 0.02602318 | I7: =(EXP(-$B$4)*($B$4^I6))/FACT(I6) -> 0.0062455632 | M7: 1 | N7: =$D$7*E8*$R$26 -> 0.14922428 | O7: =E7*E8*$R$26 -> 0.17906914 | P7: =F7*$E$8*$R$26 -> 0.10744148 | Q7: =G7*$E$8*$R$26 -> 0.042976593 | R7: =H7*$E$8*$R$26 -> 0.012892978 | S7: =I7*$E$8*$R$26 -> 0.0030943147 | U7: FORA | V7: =SUM(N7,N8,N9,N10,N11,O8,O9,O10,O11,P9,P10,P11,Q10,Q11,R11) -> 0.41003649 | X7: ACIMA UM E MEIO | Z7: =SUM(O7,O8,O9,O10,O11,N8,N9,N10,N11,P6,P7,P8,P9,P10,P11,Q6,Q7,Q8,Q9,Q10,Q11,R6,R7,R8,R9,R10,R11,S6,S7,S8,S9,S10,S11) -> 0.86641401
C8: Fora (_2) | D8: =(EXP(-$B$5)*($B$5^D6))/FACT(D6) -> 0.36787944 | E8: =(EXP(-$B$5)*($B$5^E6))/FACT(E6) -> 0.36787944 | F8: =(EXP(-$B$5)*($B$5^F6))/FACT(F6) -> 0.18393972 | G8: =(EXP(-$B$5)*($B$5^G6))/FACT(G6) -> 0.06131324 | H8: =(EXP(-$B$5)*($B$5^H6))/FACT(H6) -> 0.01532831 | I8: =(EXP(-$B$5)*($B$5^I6))/FACT(I6) -> 0.003065662 | M8: 2 | N8: =$D$7*F8*$R$26 -> 0.074612141 | O8: =F8*E7*R26 -> 0.089534569 | P8: =F7*F8*R26 -> 0.053720741 | Q8: =G7*$F$8*R26 -> 0.021488297 | R8: =H7*$F$8*R26 -> 0.006446489 | S8: =I7*$F$8*R26 -> 0.0015471574 | U8: CASA OU EMPATE | V8: =V5+V6 -> 0.85567093 | X8: ACIMA DOIS E MEIO | Z8: =SUM(N9,N10,N11,O8,O9,O10,O11,P7,P8,P9,P10,P11,Q6,Q7,Q8,Q9,Q10,Q11,R6,R7,R8,R9,R10,R11,S6,S7,S8,S9,S10,S11) -> 0.50529124
M9: 3 | N9: =$D$7*G8*R26 -> 0.024870714 | O9: =G8*E7*R26 -> 0.029844856 | P9: =G8*F7*R26 -> 0.017906914 | Q9: =G7*G8*R26 -> 0.0071627655 | R9: =H7*$G$8*R26 -> 0.0021488297 | S9: =I7*$G$8*R26 -> 0.00051571912 | U9: EMPATE OU FORA | V9: =V6+V7 -> 0.72155213 | X9: ABAIXO DOIS E MEIO | Z9: =SUM(P6,O6,N6,N7,N8,O7) -> 0.76041618
M10: 4 | N10: =D7*H8*R26 -> 0.0062176784 | O10: =H8*E7*R26 -> 0.0074612141 | P10: =H8*F7*R26 -> 0.0044767284 | Q10: =H8*G7*R26 -> 0.0017906914 | R10: =H7*H8*R26 -> 0.00053720741 | S10: =I7*$H$8*R26 -> 0.00012892978 | U10: CASA OU FORA | V10: =V5+V7 -> 0.95419179 | X10: ABAIXO TRÊS E MEIO | Z10: =SUM(N6,O6,P6,P7,O7,N7,N8,O8) -> 0.95739223
M11: 5 | N11: =D7*I8*R26 -> 0.0012435357 | O11: =I8*E7*R26 -> 0.0014922428 | P11: =I8*F7*R26 -> 0.00089534569 | Q11: =I8*G7*R26 -> 0.00035813828 | R11: =I8*H7*R26 -> 0.00010744148 | S11: =I7*I8*R26 -> 2.5785956e-05
C14: DISTÂNCIA DE FINETTI [0,2]
C15: CASA | E15: =(V5-1)^2+(V6-0)^2+(V7-0)^2 -> 0.47296631
C16: EMPATE | E16: =(V5-0)^2+(V6-1)^2+(V6-0)^2 -> 0.8671577 | N16: % Empates | O16: di² | Q16: Soma xi | R16: Soma yi
C17: FORA | E17: =(V5-0)^2+(V6-0)^2+(V7-1)^2 -> 0.74120392 | M17: 0 x 0 | N17: =7.1/100 -> 0.071 | O17: =(N17-Planilha1!N6)^2 -> 0.040108336 | Q17: =SUM(N5,O7,P8,Q9,R10,S11) -> 0.24051564 | R17: =SUM(N17,N18,N19,N20,N21,N22) -> 0.229
M18: 1 x 1 | N18: =10.1/100 -> 0.101 | O18: =(N18-Planilha1!O7)^2 -> 1.7077607e-05
M19: 2 x 2 | N19: =4.5/100 -> 0.045 | O19: =(N19-Planilha1!P8)^2 -> 0.0013215003 | Q19: xi² | R19: soma xi*yi
M20: 3 x 3 | N20: =1/100 -> 0.01 | O20: =(N20-Planilha1!Q9)^2 -> 9.3255636e-05 | Q20: =N6^2+O7^2+P8^2+Q9^2+R10^2+S11^2 -> 0.040044269 | R20: =N6*N17+O7*N18+P8*N19+Q9*N20+R10*N21+S11*N22 -> 0.025617118
M21: 4 x 4 | N21: =0.2/100 -> 0.002 | O21: =(N21-Planilha1!R10)^2 -> 3.969429e-06
M22: 5 x 5 | N22: =0 -> 0 | O22: =(N22-Planilha1!S11)^2 -> 1.1962807e-14 | Q22: yi² | R22: soma xi^2 | S22: soma yi^2
M23: r(pearson) | N23: =((6*R20-Q17*R17)/((SQRT(6*Q20-R23))*(SQRT(6*Q23-S23)))) -> 1.0147282 | Q23: =N17^2+N18^2+N19^2+N20^2+N21^2+N22^2 -> 0.017371 | R23: =Q17^2 -> 0.057847772 | S23: =R17^2 -> 0.052441
M24: α (spearman) | N24: =1-(6*(SUM(O17:O22))/(6*((6^2)-1))) -> 0.99881302
Q25: α | R25: =N17/Planilha1!N6 -> 0.26173122
Q26: β | R26: =((1-R25*N6)/(1-Planilha1!N6)) -> 1.3467512

Sheet Planilha3_Finneti
B3: Média Gols (xG) | C3: 2022/2023
A4: Time 1 (Casa) | B4: 1.2 | C4: Brighton | N4: CASA | U4: MERCADO (1, X e 2)
A5: Time 2 (Fora) | B5: 1 | C5: Chelsea | N5: 0 | O5: 1 | P5: 2 | Q5: 3 | R5: 4 | S5: 5 | U5: CASA (1) | V5: =SUM(O6,P6,P7,Q6,Q7,Q8,R6,R7,R8,R9,S6,S7,S8,S9,S10) -> 0.40405037 | X5: MERCADO DE GOLS | AB5: MERCADO AMBOS (BTTS)
L6: FORA | M6: 0 | N6: =E8*E9 -> 0.11080316 | O6: =F8*$E$9 -> 0.13296379 | P6: =G8*$E$9 -> 0.079778274 | Q6: =H8*$E$9 -> 0.03191131 | R6: =I8*$E$9 -> 0.0095733929 | S6: =J8*$E$9 -> 0.0022976143 | U6: EMPATE (X) | V6: =SUM(N6,O7,P8,Q9,R10,S11) -> 0.28939268 | X6: ACIMA DE MEIIO (+0,5) | Z6: =SUM(N6:S11)-N6 -> 0.88710332 | AB6: SIM | AC6: =SUM(O7:S11) -> 0.44036685
E7: 0 | F7: 1 | G7: 2 | H7: 3 | I7: 4 | J7: 5 | M7: 1 | N7: =$E$8*F9 -> 0.11080316 | O7: =F8*F9 -> 0.13296379 | P7: =G8*$F$9 -> 0.079778274 | Q7: =H8*$F$9 -> 0.03191131 | R7: =I8*$F$9 -> 0.0095733929 | S7: =J8*$F$9 -> 0.0022976143 | U7: FORA (2) | V7: =SUM(N7,N8,N9,N10,N11,O8,O9,O10,O11,P9,P10,P11,Q10,Q11,R11) -> 0.30446344 | X7: ACIMA UM E MEIO (+1,5) | Z7: =SUM(O7,O8,O9,O10,O11,N8,N9,N10,N11,P6,P7,P8,P9,P10,P11,Q6,Q7,Q8,Q9,Q10,Q11,R6,R7,R8,R9,R10,R11,S6,S7,S8,S9,S10,S11) -> 0.64333637 | AB7: NÃO | AC7: =1-AC6 -> 0.55963315
D8: Casa (1) | E8: =(EXP(-$B$4)*($B$4^E7))/FACT(E7) -> 0.30119421 | F8: =(EXP(-$B$4)*($B$4^F7))/FACT(F7) -> 0.36143305 | G8: =(EXP(-$B$4)*($B$4^G7))/FACT(G7) -> 0.21685983 | H8: =(EXP(-$B$4)*($B$4^H7))/FACT(H7) -> 0.086743933 | I8: =(EXP(-$B$4)*($B$4^I7))/FACT(I7) -> 0.02602318 | J8: =(EXP(-$B$4)*($B$4^J7))/FACT(J7) -> 0.0062455632 | M8: 2 | N8: =$E$8*G9 -> 0.055401579 | O8: =G9*F8 -> 0.066481895 | P8: =G8*G9 -> 0.039889137 | Q8: =H8*$G$9 -> 0.015955655 | R8: =I8*$G$9 -> 0.0047866964 | S8: =J8*$G$9 -> 0.0011488071 | X8: ACIMA DOIS E MEIO (+2,5) | Z8: =SUM(N9,N10,N11,O8,O9,O10,O11,P7,P8,P9,P10,P11,Q6,Q7,Q8,Q9,Q10,Q11,R6,R7,R8,R9,R10,R11,S6,S7,S8,S9,S10,S11) -> 0.37519273
D9: Fora (2) | E9: =(EXP(-$B$5)*($B$5^E7))/FACT(E7) -> 0.36787944 | F9: =(EXP(-$B$5)*($B$5^F7))/FACT(F7) -> 0.36787944 | G9: =(EXP(-$B$5)*($B$5^G7))/FACT(G7) -> 0.18393972 | H9: =(EXP(-$B$5)*($B$5^H7))/FACT(H7) -> 0.06131324 | I9: =(EXP(-$B$5)*($B$5^I7))/FACT(I7) -> 0.01532831 | J9: =(EXP(-$B$5)*($B$5^J7))/FACT(J7) -> 0.003065662 | M9: 3 | N9: =$E$8*H9 -> 0.018467193 | O9: =H9*F8 -> 0.022160632 | P9: =H9*G8 -> 0.013296379 | Q9: =H8*H9 -> 0.0053185516 | R9: =I8*$H$9 -> 0.0015955655 | S9: =J8*$H$9 -> 0.00038293572 | X9: ABAIXO DOIS E MEIO (-2,5) | Z9: =SUM(P6,O6,N6,N7,N8,O7) -> 0.62271375
M10: 4 | N10: =E8*I9 -> 0.0046167983 | O10: =I9*F8 -> 0.0055401579 | P10: =I9*G8 -> 0.0033240948 | Q10: =I9*H8 -> 0.0013296379 | R10: =I8*I9 -> 0.00039889137 | S10: =J8*$I$9 -> 9.5733929e-05 | X10: ABAIXO TRÊS E MEIO (-3,5) | Z10: =SUM(N6,O6,P6,P7,O7,N7,N8,O8) -> 0.76897392
M11: 5 | N11: =E8*J9 -> 0.00092335965 | O11: =J9*F8 -> 0.0011080316 | P11: =J9*G8 -> 0.00066481895 | Q11: =J9*H8 -> 0.00026592758 | R11: =J9*I8 -> 7.9778274e-05 | S11: =J8*J9 -> 1.9146786e-05 | U11: MERCADO DUPLA CHANCE
U12: CASA OU EMPATE (1X) | V12: =V5+V6 -> 0.69344304
U13: EMPATE OU FORA (X2) | V13: =V6+V7 -> 0.59385612
D14: DISTÂNCIA DE FINETTI [0,2] | H14: DISTÂNCIA DE FINETTI [0,2] | U14: CASA OU FORA (1_2) | V14: =V5+V7 -> 0.70851381
D15: CASA | F15: =(V5-1)^2+(V6-0)^2+(V7-0)^2 -> 0.53160207 | H15: CASA | J15: =(1/3-1)^2+(1/3.4-0)^2+(1/2.37-0)^2 -> 0.70898378
D16: EMPATE | F16: =(V5-0)^2+(V6-1)^2+(V6-0)^2 -> 0.75196759 | H16: EMPATE | J16: =(1/3-0)^2+(1/3.4-1)^2+(1/2.37-0)^2 -> 0.78741515
D17: FORA | F17: =(V5-0)^2+(V6-0)^2+(V7-1)^2 -> 0.73077592 | H17: FORA | J17: =(1/3-0)^2+(1/3.4-0)^2+(1/2.37-1)^2 -> 0.53176859
D20: DISTÂNCIA | E20: =MIN(F15:F17) -> 0.53160207 | H20: DISTÂNCIA | I20: =MIN(J15:J17) -> 0.53176859
D21: PRECISÃO | E21: =1-E20/2 -> 0.73419896 | H21: PRECISÃO | I21: =1-I20/2 -> 0.7341157
D22: PONTUAÇÃO | E22: =150*(E21^2)+50*E21-100 -> 17.567166 | H22: PONTUAÇÃO | I22: =150*(I21^2)+50*I21-100 -> 17.544665
B30: Média Gols (xG) | C30: 2023/2024
A31: Time 1 (Casa) | B31: 1.71 | C31: Brighton | N31: CASA | U31: MERCADO (1, X e 2)
A32: Time 2 (Fora) | B32: 1.72 | C32: Chelsea | N32: 0 | O32: 1 | P32: 2 | Q32: 3 | R32: 4 | S32: 5 | U32: CASA (1) | V32: =SUM(O33,P33,P34,Q33,Q34,Q35,R33,R34,R35,R36,S33,S34,S35,S36,S37) -> 0.37710804 | X32: MERCADO DE GOLS | AB32: MERCADO AMBOS (BTTS)
L33: FORA | M33: 0 | N33: =E35*E36 -> 0.032386941 | O33: =F35*E36 -> 0.055381669 | P33: =G35*E36 -> 0.047351327 | Q33: =H35*E36 -> 0.026990256 | R33: =I35*E36 -> 0.011538335 | S33: =J35*E36 -> 0.0039461104 | U33: EMPATE (X) | V33: =SUM(N33,O34,P35,Q36,R37,S38) -> 0.22527798 | X33: ACIMA DE MEIIO (+0,5) | Z33: =SUM(N33:S38)-N33 -> 0.95102454 | AB33: SIM | AC33: =SUM(O34:S38) -> 0.65886453
E34: 0 | F34: 1 | G34: 2 | H34: 3 | I34: 4 | J34: 5 | M34: 1 | N34: =F36*E35 -> 0.055705538 | O34: =F35*F36 -> 0.09525647 | P34: =G35*F36 -> 0.081444282 | Q34: =H35*F36 -> 0.046423241 | R34: =I35*F36 -> 0.019845935 | S34: =J35*F36 -> 0.0067873099 | U34: FORA (2) | V34: =SUM(N34,N35,N36,N37,N38,O35,O36,O37,O38,P36,P37,P38,Q37,Q38,R38) -> 0.38102545 | X34: ACIMA UM E MEIO (+1,5) | Z34: =SUM(O34,O35,O36,O37,O38,N35,N36,N37,N38,P33,P34,P35,P36,P37,P38,Q33,Q34,Q35,Q36,Q37,Q38,R33,R34,R35,R36,R37,R38,S33,S34,S35,S36,S37,S38) -> 0.83993733 | AB34: NÃO | AC34: =1-AC33 -> 0.34113547
D35: Casa (1) | E35: =(EXP(-$B$31)*($B$31^E34))/FACT(E34) -> 0.18086579 | F35: =(EXP(-$B$31)*($B$31^F34))/FACT(F34) -> 0.30928051 | G35: =(EXP(-$B$31)*($B$31^G34))/FACT(G34) -> 0.26443483 | H35: =(EXP(-$B$31)*($B$31^H34))/FACT(H34) -> 0.15072785 | I35: =(EXP(-$B$31)*($B$31^I34))/FACT(I34) -> 0.064436158 | J35: =(EXP(-$B$31)*($B$31^J34))/FACT(J34) -> 0.022037166 | M35: 2 | N35: =G36*E35 -> 0.047906763 | O35: =G36*F35 -> 0.081920564 | P35: =G35*G36 -> 0.070042083 | Q35: =H35*G36 -> 0.039923987 | R35: =I35*G36 -> 0.017067504 | S35: =J35*G36 -> 0.0058370865 | X35: ACIMA DOIS E MEIO (+2,5) | Z35: =SUM(N36,N37,N38,O35,O36,O37,O38,P34,P35,P36,P37,P38,Q33,Q34,Q35,Q36,Q37,Q38,R33,R34,R35,R36,R37,R38,S33,S34,S35,S36,S37,S38) -> 0.64942277
D36: Fora (2) | E36: =(EXP(-$B$32)*($B$32^E34))/FACT(E34) -> 0.17906615 | F36: =(EXP(-$B$32)*($B$32^F34))/FACT(F34) -> 0.30799377 | G36: =(EXP(-$B$32)*($B$32^G34))/FACT(G34) -> 0.26487465 | H36: =(EXP(-$B$32)*($B$32^H34))/FACT(H34) -> 0.15186146 | I36: =(EXP(-$B$32)*($B$32^I34))/FACT(I34) -> 0.065300429 | J36: =(EXP(-$B$32)*($B$32^J34))/FACT(J34) -> 0.022463348 | M36: 3 | N36: =H36*E35 -> 0.027466544 | O36: =H36*F35 -> 0.04696779 | P36: =H36*G35 -> 0.040157461 | Q36: =H35*H36 -> 0.022889753 | R36: =I35*H36 -> 0.0097853692 | S36: =J35*H36 -> 0.0033465963 | X36: ABAIXO DOIS E MEIO (-2,5) | Z36: =SUM(P33,O33,N33,N34,N35,O34) -> 0.33398871
M37: 4 | N37: =I36*E35 -> 0.011810614 | O37: =I36*F35 -> 0.02019615 | P37: =I36*G35 -> 0.017267708 | Q37: =I36*H35 -> 0.0098425936 | R37: =I35*I36 -> 0.0042077088 | S37: =J35*I36 -> 0.0014390364 | X37: ABAIXO TRÊS E MEIO (-3,5) | Z37: =SUM(N33,O33,P33,P34,O34,N34,N35,O35) -> 0.49735355
M38: 5 | N38: =J36*E35 -> 0.0040628512 | O38: =J36*F35 -> 0.0069474755 | P38: =J36*G35 -> 0.0059400916 | Q38: =J36*H35 -> 0.0033858522 | R38: =J36*I35 -> 0.0014474518 | S38: =J35*J36 -> 0.00049502852
D40: DISTÂNCIA DE FINETTI [0,2] | H40: DISTÂNCIA DE FINETTI [0,2]
D41: CASA | F41: =(V32-1)^2+(V33-0)^2+(V34-0)^2 -> 0.58392495 | H41: CASA | J41: =(1/2.9-1)^2+(1/3.7-0)^2+(1/2.3-0)^2 -> 0.69133283
D42: EMPATE | F42: =(V32-0)^2+(V33-1)^2+(V34-0)^2 -> 0.88758507 | H42: EMPATE | J42: =(1/2.9-0)^2+(1/3.7-1)^2+(1/2.3-0)^2 -> 0.84044746
D43: FORA | F43: =(V32-0)^2+(V33-0)^2+(V34-1)^2 -> 0.57609014 | H43: FORA | J43: =(1/2.9-0)^2+(1/3.7-0)^2+(1/2.3-1)^2 -> 0.51142278
D46: DISTÂNCIA | E46: =MIN(F41:F43) -> 0.57609014 | H46: DISTÂNCIA | I46: =MIN(J41:J43) -> 0.51142278
D47: PRECISÃO | E47: =1-E46/2 -> 0.71195493 | H47: PRECISÃO | I47: =1-I46/2 -> 0.74428861
D48: PONTUAÇÃO | E48: =150*(E47^2)+50*E47-100 -> 11.629719 | H48: PONTUAÇÃO | I48: =150*(I47^2)+50*I47-100 -> 20.30926
B58: Média Gols (xG) | C58: 2024/2025
A59: Time 1 (Casa) | B59: 1.27 | C59: Brighton | N59: CASA | U59: MERCADO (1, X e 2)
A60: Time 2 (Fora) | B60: 2.08 | C60: Chelsea | N60: 0 | O60: 1 | P60: 2 | Q60: 3 | R60: 4 | S60: 5 | U60: CASA (1) | V60: =SUM(O61,P61,P62,Q61,Q62,Q63,R61,R62,R63,R64,S61,S62,S63,S64,S65) -> 0.2274133 | X60: MERCADO DE GOLS | AB60: MERCADO AMBOS (BTTS)
L61: FORA | M61: 0 | N61: =E63*E64 -> 0.035084354 | O61: =F63*E64 -> 0.04455713 | P61: =G63*E64 -> 0.028293777 | Q61: =H63*E64 -> 0.011977699 | R61: =I63*E64 -> 0.0038029195 | S61: =J63*E64 -> 0.00096594154 | U61: EMPATE (X) | V61: =SUM(N61,O62,P63,Q64,R65,S66) -> 0.21021197 | X61: ACIMA DE MEIIO (+0,5) | Z61: =SUM(N61:S66)-N61 -> 0.94333942 | AB61: SIM | AC61: =SUM(O62:S66) -> 0.61350657
E62: 0 | F62: 1 | G62: 2 | H62: 3 | I62: 4 | J62: 5 | M62: 1 | N62: =F64*E63 -> 0.072975457 | O62: =F63*F64 -> 0.09267883 | P62: =G63*F64 -> 0.058851057 | Q62: =H63*F64 -> 0.024913614 | R62: =I63*F64 -> 0.0079100725 | S62: =J63*F64 -> 0.0020091584 | U62: FORA (2) | V62: =SUM(N62,N63,N64,N65,N66,O63,O64,O65,O66,P64,P65,P66,Q65,Q66,R66) -> 0.54079851 | X62: ACIMA UM E MEIO (+1,5) | Z62: =SUM(O62,O63,O64,O65,O66,N63,N64,N65,N66,P61,P62,P63,P64,P65,P66,Q61,Q62,Q63,Q64,Q65,Q66,R61,R62,R63,R64,R65,R66,S61,S62,S63,S64,S65,S66) -> 0.82580684 | AB62: NÃO | AC62: =1-AC61 -> 0.38649343
D63: Casa (1) | E63: =(EXP(-$B$59)*($B$59^E62))/FACT(E62) -> 0.28083162 | F63: =(EXP(-$B$59)*($B$59^F62))/FACT(F62) -> 0.35665616 | G63: =(EXP(-$B$59)*($B$59^G62))/FACT(G62) -> 0.22647666 | H63: =(EXP(-$B$59)*($B$59^H62))/FACT(H62) -> 0.09587512 | I63: =(EXP(-$B$59)*($B$59^I62))/FACT(I62) -> 0.030440351 | J63: =(EXP(-$B$59)*($B$59^J62))/FACT(J62) -> 0.0077318491 | M63: 2 | N63: =G64*E63 -> 0.075894475 | O63: =G64*F63 -> 0.096385983 | P63: =G63*G64 -> 0.061205099 | Q63: =H63*G64 -> 0.025910159 | R63: =I63*G64 -> 0.0082264754 | S63: =J63*G64 -> 0.0020895247 | X63: ACIMA DOIS E MEIO (+2,5) | Z63: =SUM(N64,N65,N66,O63,O64,O65,O66,P62,P63,P64,P65,P66,Q61,Q62,Q63,Q64,Q65,Q66,R61,R62,R63,R64,R65,R66,S61,S62,S63,S64,S65,S66) -> 0.62893976
...
